<?xml version="1.0" ?>
<sdf version="1.6">
  <model name="line_following_robot">
    <pose>0 0 0 0 0 0</pose>

    <!-- Base Link -->
    <link name="base_link">
      <pose>0 0 0.05 0 0 0</pose>
      <inertial>
         <mass>1.0</mass>
         <inertia>
            <ixx>0.01</ixx>
            <iyy>0.01</iyy>
            <izz>0.01</izz>
            <ixy>0</ixy>
            <ixz>0</ixz>
            <iyz>0</iyz>
         </inertia>
      </inertial>
      <collision name="base_collision">
         <pose>0 0 0 0 0 0</pose>
         <geometry>
           <mesh>
             <uri>model://line_following_robot/waffle_pi_base.dae</uri>
             <scale>1 1 1</scale>
           </mesh>
         </geometry>
      </collision>
      <visual name="base_visual">
         <pose>0 0 0 0 0 0</pose>
         <geometry>
           <mesh>
             <uri>model://line_following_robot/waffle_pi_base.dae</uri>
             <scale>1 1 1</scale>
           </mesh>
         </geometry>
      </visual>
    </link>

    <!-- Left Wheel -->
    <link name="left_wheel">
      <pose>0 0.15 0.05 0 0 0</pose>
      <inertial>
         <mass>0.2</mass>
         <inertia>
            <ixx>0.001</ixx>
            <iyy>0.001</iyy>
            <izz>0.001</izz>
            <ixy>0</ixy>
            <ixz>0</ixz>
            <iyz>0</iyz>
         </inertia>
      </inertial>
      <collision name="left_wheel_collision">
         <pose>0 0 0 0 0 0</pose>
         <geometry>
           <mesh>
             <uri>model://line_following_robot/tire.dae</uri>
             <scale>1 1 1</scale>
           </mesh>
         </geometry>
      </collision>
      <visual name="left_wheel_visual">
         <pose>0 0 0 0 0 0</pose>
         <geometry>
           <mesh>
             <uri>model://line_following_robot/tire.dae</uri>
             <scale>1 1 1</scale>
           </mesh>
         </geometry>
      </visual>
    </link>

    <!-- Right Wheel -->
    <link name="right_wheel">
      <pose>0 -0.15 0.05 0 0 0</pose>
      <inertial>
         <mass>0.2</mass>
         <inertia>
            <ixx>0.001</ixx>
            <iyy>0.001</iyy>
            <izz>0.001</izz>
            <ixy>0</ixy>
            <ixz>0</ixz>
            <iyz>0</iyz>
         </inertia>
      </inertial>
      <collision name="right_wheel_collision">
         <pose>0 0 0 0 0 0</pose>
         <geometry>
           <mesh>
             <uri>model://line_following_robot/tire.dae</uri>
             <scale>1 1 1</scale>
           </mesh>
         </geometry>
      </collision>
      <visual name="right_wheel_visual">
         <pose>0 0 0 0 0 0</pose>
         <geometry>
           <mesh>
             <uri>model://line_following_robot/tire.dae</uri>
             <scale>1 1 1</scale>
           </mesh>
         </geometry>
      </visual>
    </link>

    <!-- Camera Link -->
    <link name="camera_link">
      <pose>0 0 0.15 0 0 0</pose>
      <inertial>
         <mass>0.05</mass>
         <inertia>
            <ixx>0.0001</ixx>
            <iyy>0.0001</iyy>
            <izz>0.0001</izz>
            <ixy>0</ixy>
            <ixz>0</ixz>
            <iyz>0</iyz>
         </inertia>
      </inertial>
      <collision name="camera_collision">
         <pose>0 0 0 0 0 0</pose>
         <geometry>
           <box>
             <size>0.1 0.1 0.1</size>
           </box>
         </geometry>
      </collision>
      <visual name="camera_visual">
         <pose>0 0 0 0 0 0</pose>
         <geometry>
           <box>
             <size>0.1 0.1 0.1</size>
           </box>
         </geometry>
         <material>
           <ambient>0 0 1 1</ambient>
           <diffuse>0 0 1 1</diffuse>
         </material>
      </visual>
    </link>

    <!-- Joints -->
    <joint name="left_wheel_joint" type="revolute">
      <parent>base_link</parent>
      <child>left_wheel</child>
      <pose>0 0.15 0.05 0 0 0</pose>
      <axis>
         <xyz>0 0 1</xyz>
         <limit>
           <lower>-1e16</lower>
           <upper>1e16</upper>
           <effort>1e5</effort>
           <velocity>1000</velocity>
         </limit>
      </axis>
    </joint>

    <joint name="right_wheel_joint" type="revolute">
      <parent>base_link</parent>
      <child>right_wheel</child>
      <pose>0 -0.15 0.05 0 0 0</pose>
      <axis>
         <xyz>0 0 1</xyz>
         <limit>
           <lower>-1e16</lower>
           <upper>1e16</upper>
           <effort>1e5</effort>
           <velocity>1000</velocity>
         </limit>
      </axis>
    </joint>

    <!-- Diff Drive Plugin -->
    <plugin name="diff_drive_controller" filename="libgazebo_ros_diff_drive.so">
      <!-- Reference joint names must match our SDF joint names -->
      <left_joint>left_wheel_joint</left_joint>
      <right_joint>right_wheel_joint</right_joint>
      <wheel_separation>0.3</wheel_separation>
      <wheel_diameter>0.2</wheel_diameter>
      <torque>5</torque>
      <command_topic>cmd_vel</command_topic>
      <odom_topic>odom</odom_topic>
      <odom_frame>odom</odom_frame>
      <robot_base_frame>base_link</robot_base_frame>
      <update_rate>30</update_rate>
    </plugin>

    <!-- Joint State Publisher Plugin -->
    <plugin name="joint_state_publisher" filename="libgazebo_ros_joint_state_publisher.so">
      <update_rate>30</update_rate>
      <!-- Add the joint names for which you want to publish states -->
      <joint_name>left_wheel_joint</joint_name>
      <joint_name>right_wheel_joint</joint_name>
    </plugin>

  </model>
</sdf>
